Workbook

Sheet Zusammenfassung
C1: Dry-bulb temperature (°C) | E1: =Ergebnisse!C1 -> Internal gain (kW) | F1: =Ergebnisse!D1 -> Dry resultant temperature (°C) | G1: Dry resultant temperature (°C) | H1: Natürliche Lüftung | I1: Natürliche Lüftung | J1: Mechanische Lüftung
E2: =Ergebnisse!C2 -> OG02-Zone 1 | F2: =Ergebnisse!D2 -> OG02-Zone 1 | G2: =F2 -> OG02-Zone 1 | H2: Empfundene Temperatur (°C) | I2: Stunden überschreiten | J2: Empfundene Temperatur (°C)
A3: Date | B3: Time | C3: =Ergebnisse!O3 -> SMA_2035_RCP85_DRY.epw | D3: θrm | E3: =Ergebnisse!C3 -> ZOER_C1.aps | F3: =Ergebnisse!D3 -> ZOER_C1.aps | G3: When occupied | H3: Oberer Grenzwert | J3: Oberer Grenzwert
A4: Wed, 16/Apr | B4: 1 | C4: =Ergebnisse!O4 -> 0
B5: 0.041666667 | C5: =Ergebnisse!O5 -> 6.8
B6: 0.083333333 | C6: =Ergebnisse!O6 -> 4.7
B7: 0.125 | C7: =Ergebnisse!O7 -> 3.3
B8: 0.16666667 | C8: =Ergebnisse!O8 -> 3.4
B9: 0.20833333 | C9: =Ergebnisse!O9 -> 3.8
B10: 0.25 | C10: =Ergebnisse!O10 -> 3.8
B11: 0.29166667 | C11: =Ergebnisse!O11 -> 4
B12: 0.33333333 | C12: =Ergebnisse!O12 -> 4.4
B13: 0.375 | C13: =Ergebnisse!O13 -> 5
B14: 0.41666667 | C14: =Ergebnisse!O14 -> 6.7
B15: 0.45833333 | C15: =Ergebnisse!O15 -> 6.6
B16: 0.5 | C16: =Ergebnisse!O16 -> 7.4
... B27: 0.95833333 | C27: =Ergebnisse!O27 -> 6.7
A28: Thu, 17/Apr | B28: 1 | C28: =Ergebnisse!O28 -> 5.7
B29: 0.041666667 | C29: =Ergebnisse!O29 -> 6.2
B30: 0.083333333 | C30: =Ergebnisse!O30 -> 6.3
B31: 0.125 | C31: =Ergebnisse!O31 -> 5.4
B32: 0.16666667 | C32: =Ergebnisse!O32 -> 5.6
B33: 0.20833333 | C33: =Ergebnisse!O33 -> 5.7
B34: 0.25 | C34: =Ergebnisse!O34 -> 5.4
B35: 0.29166667 | C35: =Ergebnisse!O35 -> 5
B36: 0.33333333 | C36: =Ergebnisse!O36 -> 6
B37: 0.375 | C37: =Ergebnisse!O37 -> 6.3
B38: 0.41666667 | C38: =Ergebnisse!O38 -> 7.5
B39: 0.45833333 | C39: =Ergebnisse!O39 -> 9.6
B40: 0.5 | C40: =Ergebnisse!O40 -> 10.3
... B50: 0.91666667 | C50: =Ergebnisse!O50 -> 6.9
B51: 0.95833333 | C51: =Ergebnisse!O51 -> 6.4 | I51: =SUM(I52:I4755) -> 0
A52: Fri, 18/Apr | B52: 1 | C52: =Ergebnisse!O52 -> 5.2 | D52: =AVERAGE(C5:C52) -> 6.9833333 | E52: =Ergebnisse!C52 -> 0.455 | F52: =Ergebnisse!D52 -> 21.17 | G52: =IF(E52>0,F52,0) -> 21.17 | H52: =IF(D52<10,25,21.8+0.33*D52) -> 25 | I52: =IF(G52>H52,1,0) -> 0 | J52: =IF(D52<12,24.5,IF(D52>17.5,26.5,20.14+D52*0.36363636)) -> 24.5
B53: 0.041666667 | C53: =Ergebnisse!O53 -> 4.8 | D53: =AVERAGE(C6:C53) -> 6.9416667 | E53: =Ergebnisse!C53 -> 0.455 | F53: =Ergebnisse!D53 -> 21.31 | G53: =IF(E53>0,F53,0) -> 21.31 | H53: =IF(D53<10,25,21.8+0.33*D53) -> 25 | I53: =IF(G53>H53,1,0) -> 0 | J53: =IF(D53<12,24.5,IF(D53>17.5,26.5,20.14+D53*0.36363636)) -> 24.5
B54: 0.083333333 | C54: =Ergebnisse!O54 -> 5 | D54: =AVERAGE(C7:C54) -> 6.9479167 | E54: =Ergebnisse!C54 -> 0.455 | F54: =Ergebnisse!D54 -> 21.37 | G54: =IF(E54>0,F54,0) -> 21.37 | H54: =IF(D54<10,25,21.8+0.33*D54) -> 25 | I54: =IF(G54>H54,1,0) -> 0 | J54: =IF(D54<12,24.5,IF(D54>17.5,26.5,20.14+D54*0.36363636)) -> 24.5
B55: 0.125 | C55: =Ergebnisse!O55 -> 4.6 | D55: =AVERAGE(C8:C55) -> 6.975 | E55: =Ergebnisse!C55 -> 0.455 | F55: =Ergebnisse!D55 -> 21.22 | G55: =IF(E55>0,F55,0) -> 21.22 | H55: =IF(D55<10,25,21.8+0.33*D55) -> 25 | I55: =IF(G55>H55,1,0) -> 0 | J55: =IF(D55<12,24.5,IF(D55>17.5,26.5,20.14+D55*0.36363636)) -> 24.5
B56: 0.16666667 | C56: =Ergebnisse!O56 -> 4.8 | D56: =AVERAGE(C9:C56) -> 7.0041667 | E56: =Ergebnisse!C56 -> 0.455 | F56: =Ergebnisse!D56 -> 21.14 | G56: =IF(E56>0,F56,0) -> 21.14 | H56: =IF(D56<10,25,21.8+0.33*D56) -> 25 | I56: =IF(G56>H56,1,0) -> 0 | J56: =IF(D56<12,24.5,IF(D56>17.5,26.5,20.14+D56*0.36363636)) -> 24.5
B57: 0.20833333 | C57: =Ergebnisse!O57 -> 4.8 | D57: =AVERAGE(C10:C57) -> 7.025 | E57: =Ergebnisse!C57 -> 0.455 | F57: =Ergebnisse!D57 -> 21.09 | G57: =IF(E57>0,F57,0) -> 21.09 | H57: =IF(D57<10,25,21.8+0.33*D57) -> 25 | I57: =IF(G57>H57,1,0) -> 0 | J57: =IF(D57<12,24.5,IF(D57>17.5,26.5,20.14+D57*0.36363636)) -> 24.5
B58: 0.25 | C58: =Ergebnisse!O58 -> 4.6 | D58: =AVERAGE(C11:C58) -> 7.0416667 | E58: =Ergebnisse!C58 -> 0.455 | F58: =Ergebnisse!D58 -> 21.52 | G58: =IF(E58>0,F58,0) -> 21.52 | H58: =IF(D58<10,25,21.8+0.33*D58) -> 25 | I58: =IF(G58>H58,1,0) -> 0 | J58: =IF(D58<12,24.5,IF(D58>17.5,26.5,20.14+D58*0.36363636)) -> 24.5
B59: 0.29166667 | C59: =Ergebnisse!O59 -> 4.2 | D59: =AVERAGE(C12:C59) -> 7.0458333 | E59: =Ergebnisse!C59 -> 0.455 | F59: =Ergebnisse!D59 -> 21.21 | G59: =IF(E59>0,F59,0) -> 21.21 | H59: =IF(D59<10,25,21.8+0.33*D59) -> 25 | I59: =IF(G59>H59,1,0) -> 0 | J59: =IF(D59<12,24.5,IF(D59>17.5,26.5,20.14+D59*0.36363636)) -> 24.5
...

Sheet Ergebnisse
C1: Internal gain (kW) | D1: =J1 -> Dry resultant temperature (°C) | J1: Dry resultant temperature (°C) | O1: Dry-bulb temperature (°C)
C2: OG02-Zone 1 | D2: =J2 -> OG02-Zone 1 | J2: OG02-Zone 1
A3: Date | B3: Time | C3: ZOER_C1.aps | D3: =J3 -> ZOER_C1.aps | H3: Date | I3: Time | J3: ZOER_C1.aps | M3: Date | N3: Time | O3: SMA_2035_RCP85_DRY.epw
A4: Wed, 16/Apr | B4: 0.020833333 | C4: 0.455 | D4: =J4 -> 21.28 | H4: Wed, 16/Apr | I4: 0.020833333 | J4: 21.28 | M4: Wed, 16/Apr | N4: 1
B5: 0.0625 | C5: 0.455 | D5: =J5 -> 21.26 | I5: 0.0625 | J5: 21.26 | N5: 0.041666667 | O5: 6.8
B6: 0.10416667 | C6: 0.455 | D6: =J6 -> 21.27 | I6: 0.10416667 | J6: 21.27 | N6: 0.083333333 | O6: 4.7
B7: 0.14583333 | C7: 0.455 | D7: =J7 -> 21.46 | I7: 0.14583333 | J7: 21.46 | N7: 0.125 | O7: 3.3
B8: 0.1875 | C8: 0.455 | D8: =J8 -> 21.32 | I8: 0.1875 | J8: 21.32 | N8: 0.16666667 | O8: 3.4
B9: 0.22916667 | C9: 0.455 | D9: =J9 -> 21.5 | I9: 0.22916667 | J9: 21.5 | N9: 0.20833333 | O9: 3.8
B10: 0.27083333 | C10: 0.455 | D10: =J10 -> 21.18 | I10: 0.27083333 | J10: 21.18 | N10: 0.25 | O10: 3.8
B11: 0.3125 | C11: 0.455 | D11: =J11 -> 21.35 | I11: 0.3125 | J11: 21.35 | N11: 0.29166667 | O11: 4
B12: 0.35416667 | C12: 0.455 | D12: =J12 -> 21.59 | I12: 0.35416667 | J12: 21.59 | N12: 0.33333333 | O12: 4.4
B13: 0.39583333 | C13: 0.455 | D13: =J13 -> 21.02 | I13: 0.39583333 | J13: 21.02 | N13: 0.375 | O13: 5
B14: 0.4375 | C14: 0.455 | D14: =J14 -> 21.21 | I14: 0.4375 | J14: 21.21 | N14: 0.41666667 | O14: 6.7
B15: 0.47916667 | C15: 0.455 | D15: =J15 -> 20.83 | I15: 0.47916667 | J15: 20.83 | N15: 0.45833333 | O15: 6.6
B16: 0.52083333 | C16: 0.455 | D16: =J16 -> 20.89 | I16: 0.52083333 | J16: 20.89 | N16: 0.5 | O16: 7.4
... B27: 0.97916667 | C27: 0.455 | D27: =J27 -> 21.23 | I27: 0.97916667 | J27: 21.23 | N27: 0.95833333 | O27: 6.7
A28: Thu, 17/Apr | B28: 0.020833333 | C28: 0.455 | D28: =J28 -> 21.27 | H28: Thu, 17/Apr | I28: 0.020833333 | J28: 21.27 | M28: Thu, 17/Apr | N28: 1 | O28: 5.7
B29: 0.0625 | C29: 0.455 | D29: =J29 -> 21.26 | I29: 0.0625 | J29: 21.26 | N29: 0.041666667 | O29: 6.2
B30: 0.10416667 | C30: 0.455 | D30: =J30 -> 21.41 | I30: 0.10416667 | J30: 21.41 | N30: 0.083333333 | O30: 6.3
B31: 0.14583333 | C31: 0.455 | D31: =J31 -> 21.46 | I31: 0.14583333 | J31: 21.46 | N31: 0.125 | O31: 5.4
B32: 0.1875 | C32: 0.455 | D32: =J32 -> 21.33 | I32: 0.1875 | J32: 21.33 | N32: 0.16666667 | O32: 5.6
B33: 0.22916667 | C33: 0.455 | D33: =J33 -> 21.25 | I33: 0.22916667 | J33: 21.25 | N33: 0.20833333 | O33: 5.7
B34: 0.27083333 | C34: 0.455 | D34: =J34 -> 21.2 | I34: 0.27083333 | J34: 21.2 | N34: 0.25 | O34: 5.4
B35: 0.3125 | C35: 0.455 | D35: =J35 -> 21.29 | I35: 0.3125 | J35: 21.29 | N35: 0.29166667 | O35: 5
B36: 0.35416667 | C36: 0.455 | D36: =J36 -> 21.41 | I36: 0.35416667 | J36: 21.41 | N36: 0.33333333 | O36: 6
B37: 0.39583333 | C37: 0.455 | D37: =J37 -> 21.52 | I37: 0.39583333 | J37: 21.52 | N37: 0.375 | O37: 6.3
B38: 0.4375 | C38: 0.455 | D38: =J38 -> 21.05 | I38: 0.4375 | J38: 21.05 | N38: 0.41666667 | O38: 7.5
B39: 0.47916667 | C39: 0.455 | D39: =J39 -> 21.11 | I39: 0.47916667 | J39: 21.11 | N39: 0.45833333 | O39: 9.6
B40: 0.52083333 | C40: 0.455 | D40: =J40 -> 21.03 | I40: 0.52083333 | J40: 21.03 | N40: 0.5 | O40: 10.3
... B51: 0.97916667 | C51: 0.455 | D51: =J51 -> 21.28 | I51: 0.97916667 | J51: 21.28 | N51: 0.95833333 | O51: 6.4
A52: Fri, 18/Apr | B52: 0.020833333 | C52: 0.455 | D52: =J52 -> 21.17 | H52: Fri, 18/Apr | I52: 0.020833333 | J52: 21.17 | M52: Fri, 18/Apr | N52: 1 | O52: 5.2
B53: 0.0625 | C53: 0.455 | D53: =J53 -> 21.31 | I53: 0.0625 | J53: 21.31 | N53: 0.041666667 | O53: 4.8
B54: 0.10416667 | C54: 0.455 | D54: =J54 -> 21.37 | I54: 0.10416667 | J54: 21.37 | N54: 0.083333333 | O54: 5
B55: 0.14583333 | C55: 0.455 | D55: =J55 -> 21.22 | I55: 0.14583333 | J55: 21.22 | N55: 0.125 | O55: 4.6
B56: 0.1875 | C56: 0.455 | D56: =J56 -> 21.14 | I56: 0.1875 | J56: 21.14 | N56: 0.16666667 | O56: 4.8
B57: 0.22916667 | C57: 0.455 | D57: =J57 -> 21.09 | I57: 0.22916667 | J57: 21.09 | N57: 0.20833333 | O57: 4.8
B58: 0.27083333 | C58: 0.455 | D58: =J58 -> 21.52 | I58: 0.27083333 | J58: 21.52 | N58: 0.25 | O58: 4.6
B59: 0.3125 | C59: 0.455 | D59: =J59 -> 21.21 | I59: 0.3125 | J59: 21.21 | N59: 0.29166667 | O59: 4.2
B60: 0.35416667 | C60: 0.455 | D60: =J60 -> 21.24 | I60: 0.35416667 | J60: 21.24 | N60: 0.33333333 | O60: 3.7
...

Sheet Grafik
H41: Obere Grenzkurve - maximale operative Temperatur
H43: Untere Grenzkurve - minimale operative Temperatur
