Workbook

Sheet Zusammenfassung
C1: Dry-bulb temperature (°C) | E1: People gain (kW) | F1: Dry resultant temperature (°C) | G1: Dry resultant temperature (°C) | J1: Mechanische Lüftung | K1: Mechanische Lüftung | L1: Mechanische Lüftung
J2: Empfundene Temperatur (°C) | K2: Stunden überschreiten | L2: Stunden >26oC
A3: Date | B3: Time | C3: =Ergebnisse!D4 -> Date | D3: θrm | G3: When occupied | J3: Obere Grenzwert
A4: Thu, 16/Apr | B4: 1 | C4: =Ergebnisse!C5 -> 6.8
B5: 0.041666667 | C5: =Ergebnisse!C6 -> 6.8
B6: 0.083333333 | C6: =Ergebnisse!C7 -> 4.7
B7: 0.125 | C7: =Ergebnisse!C8 -> 3.3
B8: 0.16666667 | C8: =Ergebnisse!C9 -> 3.4
B9: 0.20833333 | C9: =Ergebnisse!C10 -> 3.8
B10: 0.25 | C10: =Ergebnisse!C11 -> 3.8
B11: 0.29166667 | C11: =Ergebnisse!C12 -> 4
B12: 0.33333333 | C12: =Ergebnisse!C13 -> 4.4
B13: 0.375 | C13: =Ergebnisse!C14 -> 5
B14: 0.41666667 | C14: =Ergebnisse!C15 -> 6.7
B15: 0.45833333 | C15: =Ergebnisse!C16 -> 6.6
B16: 0.5 | C16: =Ergebnisse!C17 -> 7.4
... B27: 0.95833333 | C27: =Ergebnisse!C28 -> 6.7
A28: Fri, 17/Apr | B28: 1 | C28: =Ergebnisse!C29 -> 5.7
B29: 0.041666667 | C29: =Ergebnisse!C30 -> 6.2
B30: 0.083333333 | C30: =Ergebnisse!C31 -> 6.3
B31: 0.125 | C31: =Ergebnisse!C32 -> 5.4
B32: 0.16666667 | C32: =Ergebnisse!C33 -> 5.6
B33: 0.20833333 | C33: =Ergebnisse!C34 -> 5.7
B34: 0.25 | C34: =Ergebnisse!C35 -> 5.4
B35: 0.29166667 | C35: =Ergebnisse!C36 -> 5
B36: 0.33333333 | C36: =Ergebnisse!C37 -> 6
B37: 0.375 | C37: =Ergebnisse!C38 -> 6.3
B38: 0.41666667 | C38: =Ergebnisse!C39 -> 7.5
B39: 0.45833333 | C39: =Ergebnisse!C40 -> 9.6
B40: 0.5 | C40: =Ergebnisse!C41 -> 10.3
... B50: 0.91666667 | C50: =Ergebnisse!C51 -> 6.9
B51: 0.95833333 | C51: =Ergebnisse!C52 -> 6.4 | K51: =SUM(K52:K5160) -> 0 | L51: =SUM(L52:L5160) -> 0
A52: Sat, 18/Apr | B52: 1 | C52: =Ergebnisse!C53 -> 5.2 | D52: =AVERAGE(C5:C52) -> 6.9833333 | E52: =Ergebnisse!J53 -> 0 | F52: =Ergebnisse!F53 -> 22.65 | G52: =IF(E52>0,F52,0) -> 0 | J52: =IF(D52<12,24.5,IF(D52>17.5,26.5,20.14+D52*0.36363636)) -> 24.5 | K52: =IF(G52>J52,1,0) -> 0 | L52: =IF(G52>26,1,0) -> 0
B53: 0.041666667 | C53: =Ergebnisse!C54 -> 4.8 | D53: =AVERAGE(C6:C53) -> 6.9416667 | E53: =Ergebnisse!J54 -> 0 | F53: =Ergebnisse!F54 -> 22.52 | G53: =IF(E53>0,F53,0) -> 0 | J53: =IF(D53<12,24.5,IF(D53>17.5,26.5,20.14+D53*0.36363636)) -> 24.5 | K53: =IF(G53>J53,1,0) -> 0 | L53: =IF(G53>26,1,0) -> 0
B54: 0.083333333 | C54: =Ergebnisse!C55 -> 5 | D54: =AVERAGE(C7:C54) -> 6.9479167 | E54: =Ergebnisse!J55 -> 0 | F54: =Ergebnisse!F55 -> 22.39 | G54: =IF(E54>0,F54,0) -> 0 | J54: =IF(D54<12,24.5,IF(D54>17.5,26.5,20.14+D54*0.36363636)) -> 24.5 | K54: =IF(G54>J54,1,0) -> 0 | L54: =IF(G54>26,1,0) -> 0
B55: 0.125 | C55: =Ergebnisse!C56 -> 4.6 | D55: =AVERAGE(C8:C55) -> 6.975 | E55: =Ergebnisse!J56 -> 0 | F55: =Ergebnisse!F56 -> 22.26 | G55: =IF(E55>0,F55,0) -> 0 | J55: =IF(D55<12,24.5,IF(D55>17.5,26.5,20.14+D55*0.36363636)) -> 24.5 | K55: =IF(G55>J55,1,0) -> 0 | L55: =IF(G55>26,1,0) -> 0
B56: 0.16666667 | C56: =Ergebnisse!C57 -> 4.8 | D56: =AVERAGE(C9:C56) -> 7.0041667 | E56: =Ergebnisse!J57 -> 0 | F56: =Ergebnisse!F57 -> 22.15 | G56: =IF(E56>0,F56,0) -> 0 | J56: =IF(D56<12,24.5,IF(D56>17.5,26.5,20.14+D56*0.36363636)) -> 24.5 | K56: =IF(G56>J56,1,0) -> 0 | L56: =IF(G56>26,1,0) -> 0
B57: 0.20833333 | C57: =Ergebnisse!C58 -> 4.8 | D57: =AVERAGE(C10:C57) -> 7.025 | E57: =Ergebnisse!J58 -> 0 | F57: =Ergebnisse!F58 -> 22.04 | G57: =IF(E57>0,F57,0) -> 0 | J57: =IF(D57<12,24.5,IF(D57>17.5,26.5,20.14+D57*0.36363636)) -> 24.5 | K57: =IF(G57>J57,1,0) -> 0 | L57: =IF(G57>26,1,0) -> 0
B58: 0.25 | C58: =Ergebnisse!C59 -> 4.6 | D58: =AVERAGE(C11:C58) -> 7.0416667 | E58: =Ergebnisse!J59 -> 0 | F58: =Ergebnisse!F59 -> 22.07 | G58: =IF(E58>0,F58,0) -> 0 | J58: =IF(D58<12,24.5,IF(D58>17.5,26.5,20.14+D58*0.36363636)) -> 24.5 | K58: =IF(G58>J58,1,0) -> 0 | L58: =IF(G58>26,1,0) -> 0
B59: 0.29166667 | C59: =Ergebnisse!C60 -> 4.2 | D59: =AVERAGE(C12:C59) -> 7.0458333 | E59: =Ergebnisse!J60 -> 0.462 | F59: =Ergebnisse!F60 -> 22.61 | G59: =IF(E59>0,F59,0) -> 22.61 | J59: =IF(D59<12,24.5,IF(D59>17.5,26.5,20.14+D59*0.36363636)) -> 24.5 | K59: =IF(G59>J59,1,0) -> 0 | L59: =IF(G59>26,1,0) -> 0
...

Sheet Ergebnisse
A1: Paste below: dry-bulb | D1: Paste below: dry resultant | G1: Paste below: people gain
C2: Dry-bulb temperature (°C) | F2: Dry resultant temperature (°C) | I2: People gain (kW)
F3: OG05-Zone 3 | I3: OG05-Zone 3
A4: Date | B4: Time | C4: SMA_2035_RCP85_DRY.epw | D4: Date | E4: Time | F4: ZOER_C2.aps | G4: Date | H4: Time | I4: ZOER_C2.aps
A5: Thu, 16/Apr | B5: 1 | C5: 6.8 | D5: Wed, 16/Apr | E5: 0.020833333 | F5: 22.72 | G5: Wed, 16/Apr | H5: 0.020833333 | I5: 0 | J5: 0
B6: 0.041666667 | C6: 6.8 | E6: 0.0625 | F6: 22.56 | H6: 0.0625 | I6: 0 | J6: =IF(I6=0,I5,I6) -> 0
B7: 0.083333333 | C7: 4.7 | E7: 0.10416667 | F7: 22.39 | H7: 0.10416667 | I7: 0 | J7: =IF(I7=0,I6,I7) -> 0
B8: 0.125 | C8: 3.3 | E8: 0.14583333 | F8: 22.24 | H8: 0.14583333 | I8: 0 | J8: =IF(I8=0,I7,I8) -> 0
B9: 0.16666667 | C9: 3.4 | E9: 0.1875 | F9: 22.11 | H9: 0.1875 | I9: 0 | J9: =IF(I9=0,I8,I9) -> 0
B10: 0.20833333 | C10: 3.8 | E10: 0.22916667 | F10: 22.01 | H10: 0.22916667 | I10: 0 | J10: =IF(I10=0,I9,I10) -> 0
B11: 0.25 | C11: 3.8 | E11: 0.27083333 | F11: 22.06 | H11: 0.27083333 | I11: 0 | J11: =IF(I11=0,I10,I11) -> 0
B12: 0.29166667 | C12: 4 | E12: 0.3125 | F12: 22.73 | H12: 0.3125 | I12: 0.462 | J12: =IF(I12=0,I11,I12) -> 0.462
B13: 0.33333333 | C13: 4.4 | E13: 0.35416667 | F13: 23.4 | H13: 0.35416667 | I13: 0.693 | J13: =IF(I13=0,I12,I13) -> 0.693
B14: 0.375 | C14: 5 | E14: 0.39583333 | F14: 23.99 | H14: 0.39583333 | I14: 1.155 | J14: =IF(I14=0,I13,I14) -> 1.155
B15: 0.41666667 | C15: 6.7 | E15: 0.4375 | F15: 24.01 | H15: 0.4375 | I15: 1.155 | J15: =IF(I15=0,I14,I15) -> 1.155
B16: 0.45833333 | C16: 6.6 | E16: 0.47916667 | F16: 24 | H16: 0.47916667 | I16: 0.924 | J16: =IF(I16=0,I15,I16) -> 0.924
B17: 0.5 | C17: 7.4 | E17: 0.52083333 | F17: 23.94 | H17: 0.52083333 | I17: 0.231 | J17: =IF(I17=0,I16,I17) -> 0.231
... B28: 0.95833333 | C28: 6.7 | E28: 0.97916667 | F28: 22.95 | H28: 0.97916667 | I28: 0 | J28: =IF(I28=0,I27,I28) -> 0
A29: Fri, 17/Apr | B29: 1 | C29: 5.7 | D29: Thu, 17/Apr | E29: 0.020833333 | F29: 22.8 | G29: Thu, 17/Apr | H29: 0.020833333 | I29: 0 | J29: =IF(I29=0,I28,I29) -> 0
B30: 0.041666667 | C30: 6.2 | E30: 0.0625 | F30: 22.68 | H30: 0.0625 | I30: 0 | J30: =IF(I30=0,I29,I30) -> 0
B31: 0.083333333 | C31: 6.3 | E31: 0.10416667 | F31: 22.56 | H31: 0.10416667 | I31: 0 | J31: =IF(I31=0,I30,I31) -> 0
B32: 0.125 | C32: 5.4 | E32: 0.14583333 | F32: 22.43 | H32: 0.14583333 | I32: 0 | J32: =IF(I32=0,I31,I32) -> 0
B33: 0.16666667 | C33: 5.6 | E33: 0.1875 | F33: 22.31 | H33: 0.1875 | I33: 0 | J33: =IF(I33=0,I32,I33) -> 0
B34: 0.20833333 | C34: 5.7 | E34: 0.22916667 | F34: 22.21 | H34: 0.22916667 | I34: 0 | J34: =IF(I34=0,I33,I34) -> 0
B35: 0.25 | C35: 5.4 | E35: 0.27083333 | F35: 22.26 | H35: 0.27083333 | I35: 0 | J35: =IF(I35=0,I34,I35) -> 0
B36: 0.29166667 | C36: 5 | E36: 0.3125 | F36: 22.92 | H36: 0.3125 | I36: 0.462 | J36: =IF(I36=0,I35,I36) -> 0.462
B37: 0.33333333 | C37: 6 | E37: 0.35416667 | F37: 23.58 | H37: 0.35416667 | I37: 0.693 | J37: =IF(I37=0,I36,I37) -> 0.693
B38: 0.375 | C38: 6.3 | E38: 0.39583333 | F38: 24.01 | H38: 0.39583333 | I38: 1.155 | J38: =IF(I38=0,I37,I38) -> 1.155
B39: 0.41666667 | C39: 7.5 | E39: 0.4375 | F39: 24 | H39: 0.4375 | I39: 1.155 | J39: =IF(I39=0,I38,I39) -> 1.155
B40: 0.45833333 | C40: 9.6 | E40: 0.47916667 | F40: 24.01 | H40: 0.47916667 | I40: 0.924 | J40: =IF(I40=0,I39,I40) -> 0.924
B41: 0.5 | C41: 10.3 | E41: 0.52083333 | F41: 24 | H41: 0.52083333 | I41: 0.231 | J41: =IF(I41=0,I40,I41) -> 0.231
... B52: 0.95833333 | C52: 6.4 | E52: 0.97916667 | F52: 22.81 | H52: 0.97916667 | I52: 0 | J52: =IF(I52=0,I51,I52) -> 0
A53: Sat, 18/Apr | B53: 1 | C53: 5.2 | D53: Fri, 18/Apr | E53: 0.020833333 | F53: 22.65 | G53: Fri, 18/Apr | H53: 0.020833333 | I53: 0 | J53: =IF(I53=0,I52,I53) -> 0
B54: 0.041666667 | C54: 4.8 | E54: 0.0625 | F54: 22.52 | H54: 0.0625 | I54: 0 | J54: =IF(I54=0,I53,I54) -> 0
B55: 0.083333333 | C55: 5 | E55: 0.10416667 | F55: 22.39 | H55: 0.10416667 | I55: 0 | J55: =IF(I55=0,I54,I55) -> 0
B56: 0.125 | C56: 4.6 | E56: 0.14583333 | F56: 22.26 | H56: 0.14583333 | I56: 0 | J56: =IF(I56=0,I55,I56) -> 0
B57: 0.16666667 | C57: 4.8 | E57: 0.1875 | F57: 22.15 | H57: 0.1875 | I57: 0 | J57: =IF(I57=0,I56,I57) -> 0
B58: 0.20833333 | C58: 4.8 | E58: 0.22916667 | F58: 22.04 | H58: 0.22916667 | I58: 0 | J58: =IF(I58=0,I57,I58) -> 0
B59: 0.25 | C59: 4.6 | E59: 0.27083333 | F59: 22.07 | H59: 0.27083333 | I59: 0 | J59: =IF(I59=0,I58,I59) -> 0
B60: 0.29166667 | C60: 4.2 | E60: 0.3125 | F60: 22.61 | H60: 0.3125 | I60: 0.462 | J60: =IF(I60=0,I59,I60) -> 0.462
...

Sheet Grafik
H41: Obere Grenzkurve - maximale operative Temperatur
H42: Obere Behaglichkeitsgrenze
H43: Untere Grenzkurve - minimale operative Temperatur
